2024-12-01 12:50:44,201 - INFO - Proxy file generated successfully
2024-12-01 12:50:44,204 - INFO - Created proxy list with 20 proxies
2024-12-01 12:50:45,343 - INFO - Table headings: ['Feature', 'Python', 'C', 'C++', 'Java']
2024-12-01 12:50:45,343 - INFO - Row 1: ['Interpreted', 'Compiled', 'Compiled', 'CompiledandInterpreted']
2024-12-01 12:50:45,343 - WARNING - Skipping row 1: 4 columns (expected 5)
2024-12-01 12:50:45,343 - INFO - Row 2: ['Multi-paradigm(object-orientedproceduralfunctional)', 'Proceduralstructured', 'Multi-paradigm(proceduralobject-orientedgeneric)', 'Object-orientedstructured']
2024-12-01 12:50:45,357 - WARNING - Skipping row 2: 4 columns (expected 5)
2024-12-01 12:50:45,357 - INFO - Row 3: ['Automatic', 'Manual', 'Manual', 'Automatic']
2024-12-01 12:50:45,357 - WARNING - Skipping row 3: 4 columns (expected 5)
2024-12-01 12:50:45,357 - INFO - Row 4: ['Simple', 'Complex', 'Complex', 'Complex']
2024-12-01 12:50:45,358 - WARNING - Skipping row 4: 4 columns (expected 5)
2024-12-01 12:50:45,358 - INFO - Row 5: ['High', 'High', 'High', 'High']
2024-12-01 12:50:45,358 - WARNING - Skipping row 5: 4 columns (expected 5)
2024-12-01 12:50:45,358 - INFO - Row 6: ['Webdevelopmentdataanalysismachinelearning', 'Systemprogrammingembeddedsystemsgamedevelopment', 'Systemprogramminggamedevelopmenthigh-performanceapplications', 'Large-scaleapplicationsenterprisesoftware']
2024-12-01 12:50:45,358 - WARNING - Skipping row 6: 4 columns (expected 5)
2024-12-01 12:50:45,358 - INFO - Row 7: ['DjangoFlask', 'StandardLibrary', 'StandardLibraryBoost', 'SpringHibernate']
2024-12-01 12:50:45,358 - WARNING - Skipping row 7: 4 columns (expected 5)
2024-12-01 12:50:45,358 - INFO - Row 8: ['Moderate', 'Steep', 'Steep', 'Moderate']
2024-12-01 12:50:45,358 - WARNING - Skipping row 8: 4 columns (expected 5)
2024-12-01 12:50:45,358 - INFO - Row 9: ['Strong', 'Strong', 'Strong', 'Strong']
2024-12-01 12:50:45,358 - WARNING - Skipping row 9: 4 columns (expected 5)
2024-12-01 12:50:45,358 - INFO - Row 10: ['Abundant', 'Abundant', 'Abundant', 'Abundant']
2024-12-01 12:50:45,358 - WARNING - Skipping row 10: 4 columns (expected 5)
2024-12-01 12:50:45,358 - WARNING - No valid rows found in the table
2024-12-01 12:50:45,358 - INFO - Table headings: ['Company', 'Description']
2024-12-01 12:50:45,358 - INFO - Row 1: ['Google', 'UsesPythonforvariousapplicationsincludingtheirsearchengineandmachinelearningprojects.']
2024-12-01 12:50:45,358 - INFO - Row 2: ['Instagram', 'ThebackendofInstagramisbuiltusingPythonenablingittohandlemillionsofusersefficiently.']
2024-12-01 12:50:45,358 - INFO - Row 3: ['Spotify', 'Pythonisusedfordataanalysisandbackendserviceshelpingimproveuserrecommendations.']
2024-12-01 12:50:45,358 - INFO - Row 4: ['Dropbox', 'PythonpowersthedesktopclientofDropboxmakingiteasytosyncfilesacrossdevices.']
2024-12-01 12:50:45,358 - INFO - Row 5: ['Netflix', 'PythonhelpsNetflixwithdataanalysisandmanagingitscontentrecommendationalgorithms.']
2024-12-01 12:50:45,358 - INFO - Row 6: ['Reddit', 'OneofthelargestonlinecommunitiesRedditusesPythonforitscorefunctionalities.']
2024-12-01 12:50:45,358 - INFO - Row 7: ['Uber', 'UberusesPythonforvariousfeaturesincludingdynamicpricinganddataanalysis.']
2024-12-01 12:50:45,358 - INFO - Row 8: ['Pinterest', 'PythonplaysakeyroleinthebackendofPinteresthelpingscaleandmanageusercontent.']
2024-12-01 12:50:45,358 - INFO - Table headings: ['Career', 'Average Salary (INR) Per Annum', 'Average Salary (USD) Per Annum']
2024-12-01 12:50:45,360 - INFO - Row 1: ['PythonDeveloper', '\u20b9500000–\u20b91200000', '$60000–$110000']
2024-12-01 12:50:45,362 - INFO - Row 2: ['DataScientist', '\u20b9600000–\u20b91500000', '$70000–$130000']
2024-12-01 12:50:45,362 - INFO - Row 3: ['MachineLearningEngineer', '\u20b9700000–\u20b91800000', '$75000–$140000']
2024-12-01 12:50:45,362 - INFO - Row 4: ['FullStackDeveloper', '\u20b9600000–\u20b91300000', '$65000–$120000']
2024-12-01 12:50:45,362 - INFO - Row 5: ['DevOpsEngineer', '\u20b9800000–\u20b92000000', '$80000–$140000']
2024-12-01 12:50:45,362 - INFO - Row 6: ['AutomationEngineer', '\u20b9500000–\u20b91200000', '$55000–$100000']
2024-12-01 12:50:45,362 - INFO - Row 7: ['DataAnalyst', '\u20b9400000–\u20b9900000', '$50000–$90000']
2024-12-01 12:50:45,362 - INFO - Row 8: ['SoftwareEngineer', '\u20b9500000–\u20b91500000', '$65000–$120000']
2024-12-01 12:50:45,362 - INFO - Row 9: ['BackendDeveloper', '\u20b9600000–\u20b91300000', '$70000–$125000']
2024-12-01 12:50:45,362 - INFO - Row 10: ['AIEngineer', '\u20b9900000–\u20b92500000', '$90000–$160000']
2024-12-01 12:50:45,364 - INFO - DataFrame columns: Index(['Company', 'Description'], dtype='object')
2024-12-01 12:50:45,364 - INFO - DataFrame shape: (8, 2)
2024-12-01 12:50:45,384 - INFO - Saved DataFrame to c:\Users\awast\OneDrive\Desktop\vscode\mdg\b27_project_again\web_scraping\data/python.csv
2024-12-01 12:50:45,388 - INFO - DataFrame columns: Index(['Career', 'Average Salary (INR) Per Annum',
       'Average Salary (USD) Per Annum'],
      dtype='object')
2024-12-01 12:50:45,388 - INFO - DataFrame shape: (10, 3)
2024-12-01 12:50:45,389 - INFO - Saved DataFrame to c:\Users\awast\OneDrive\Desktop\vscode\mdg\b27_project_again\web_scraping\data/python.csv
2024-12-01 12:51:00,413 - INFO - Proxy file generated successfully
2024-12-01 12:51:00,416 - INFO - Created proxy list with 20 proxies
2024-12-01 12:52:31,095 - INFO - Proxy file generated successfully
2024-12-01 12:52:31,097 - INFO - Created proxy list with 20 proxies
2024-12-01 12:53:43,445 - INFO - Proxy file generated successfully
2024-12-01 12:53:43,446 - INFO - Created proxy list with 20 proxies
2024-12-01 12:54:16,470 - INFO - Proxy file generated successfully
2024-12-01 12:54:16,470 - INFO - Created proxy list with 20 proxies
2024-12-01 12:54:16,823 - INFO - Proxy file generated successfully
2024-12-01 12:54:16,825 - INFO - Created proxy list with 20 proxies
2024-12-01 12:54:35,221 - INFO - Proxy file generated successfully
2024-12-01 12:54:35,221 - INFO - Created proxy list with 20 proxies
2024-12-01 12:54:35,223 - ERROR - Error in search: list index out of range
2024-12-01 12:54:35,223 - ERROR - Traceback (most recent call last):
  File "c:\Users\awast\OneDrive\Desktop\vscode\mdg\b27_project_again\web_scraping\main.py", line 83, in search
    proxy = self.get_random_proxy()
            ^^^^^^^^^^^^^^^^^^^^^^^
  File "c:\Users\awast\OneDrive\Desktop\vscode\mdg\b27_project_again\web_scraping\main.py", line 73, in get_random_proxy
    if self.time_file_update_check(current_hour, current_minute):
       ^^^^^^^^^^^^^^^^^^^^^^^^^^^^^^^^^^^^^^^^^^^^^^^^^^^^^^^^^
  File "c:\Users\awast\OneDrive\Desktop\vscode\mdg\b27_project_again\web_scraping\main.py", line 56, in time_file_update_check
    prevHour = int(timeString.split(' ')[1].split(':')[0])
                   ~~~~~~~~~~~~~~~~~~~~~^^^
IndexError: list index out of range

2024-12-01 12:55:07,468 - INFO - Proxy file generated successfully
2024-12-01 12:55:07,475 - INFO - Created proxy list with 20 proxies
2024-12-01 12:55:56,895 - INFO - Proxy file generated successfully
2024-12-01 12:55:56,895 - INFO - Created proxy list with 20 proxies
2024-12-01 12:55:57,240 - INFO - Proxy file generated successfully
2024-12-01 12:55:57,244 - INFO - Created proxy list with 20 proxies
2024-12-01 12:57:05,408 - INFO - Proxy file generated successfully
2024-12-01 12:57:05,409 - INFO - Created proxy list with 20 proxies
2024-12-01 12:57:05,409 - ERROR - Error in search: remove() takes exactly 1 positional argument (2 given)
2024-12-01 12:57:05,409 - ERROR - Traceback (most recent call last):
  File "c:\Users\awast\OneDrive\Desktop\vscode\mdg\b27_project_again\web_scraping\main.py", line 84, in search
    proxy = self.get_random_proxy()
            ^^^^^^^^^^^^^^^^^^^^^^^
  File "c:\Users\awast\OneDrive\Desktop\vscode\mdg\b27_project_again\web_scraping\main.py", line 76, in get_random_proxy
    os.remove(os.path.dirname(__file__), 'data/time.txt')
TypeError: remove() takes exactly 1 positional argument (2 given)

2024-12-01 12:57:13,708 - INFO - Proxy file generated successfully
2024-12-01 12:57:13,719 - INFO - Created proxy list with 20 proxies
2024-12-01 12:57:49,489 - INFO - Proxy file generated successfully
2024-12-01 12:57:49,492 - INFO - Created proxy list with 20 proxies
2024-12-01 12:57:49,851 - INFO - Proxy file generated successfully
2024-12-01 12:57:49,853 - INFO - Created proxy list with 20 proxies
2024-12-01 12:58:10,879 - ERROR - Error in search: HTTPSConnectionPool(host='www.google.com', port=443): Max retries exceeded with url: /search?q=DFS%20geekforgeeks (Caused by ProxyError('Unable to connect to proxy', ConnectTimeoutError(<urllib3.connection.HTTPSConnection object at 0x000001FDB9347F50>, 'Connection to 103.37.201.178 timed out. (connect timeout=None)')))
2024-12-01 12:58:10,960 - ERROR - Traceback (most recent call last):
  File "C:\Users\awast\AppData\Local\Packages\PythonSoftwareFoundation.Python.3.12_qbz5n2kfra8p0\LocalCache\local-packages\Python312\site-packages\urllib3\connection.py", line 196, in _new_conn
    sock = connection.create_connection(
           ^^^^^^^^^^^^^^^^^^^^^^^^^^^^^
  File "C:\Users\awast\AppData\Local\Packages\PythonSoftwareFoundation.Python.3.12_qbz5n2kfra8p0\LocalCache\local-packages\Python312\site-packages\urllib3\util\connection.py", line 85, in create_connection
    raise err
  File "C:\Users\awast\AppData\Local\Packages\PythonSoftwareFoundation.Python.3.12_qbz5n2kfra8p0\LocalCache\local-packages\Python312\site-packages\urllib3\util\connection.py", line 73, in create_connection
    sock.connect(sa)
TimeoutError: [WinError 10060] A connection attempt failed because the connected party did not properly respond after a period of time, or established connection failed because connected host has failed to respond

The above exception was the direct cause of the following exception:

Traceback (most recent call last):
  File "C:\Users\awast\AppData\Local\Packages\PythonSoftwareFoundation.Python.3.12_qbz5n2kfra8p0\LocalCache\local-packages\Python312\site-packages\urllib3\connectionpool.py", line 775, in urlopen
    self._prepare_proxy(conn)
  File "C:\Users\awast\AppData\Local\Packages\PythonSoftwareFoundation.Python.3.12_qbz5n2kfra8p0\LocalCache\local-packages\Python312\site-packages\urllib3\connectionpool.py", line 1044, in _prepare_proxy
    conn.connect()
  File "C:\Users\awast\AppData\Local\Packages\PythonSoftwareFoundation.Python.3.12_qbz5n2kfra8p0\LocalCache\local-packages\Python312\site-packages\urllib3\connection.py", line 615, in connect
    self.sock = sock = self._new_conn()
                       ^^^^^^^^^^^^^^^^
  File "C:\Users\awast\AppData\Local\Packages\PythonSoftwareFoundation.Python.3.12_qbz5n2kfra8p0\LocalCache\local-packages\Python312\site-packages\urllib3\connection.py", line 205, in _new_conn
    raise ConnectTimeoutError(
urllib3.exceptions.ConnectTimeoutError: (<urllib3.connection.HTTPSConnection object at 0x000001FDB9347F50>, 'Connection to 103.37.201.178 timed out. (connect timeout=None)')

The above exception was the direct cause of the following exception:

urllib3.exceptions.ProxyError: ('Unable to connect to proxy', ConnectTimeoutError(<urllib3.connection.HTTPSConnection object at 0x000001FDB9347F50>, 'Connection to 103.37.201.178 timed out. (connect timeout=None)'))

The above exception was the direct cause of the following exception:

Traceback (most recent call last):
  File "C:\Users\awast\AppData\Local\Packages\PythonSoftwareFoundation.Python.3.12_qbz5n2kfra8p0\LocalCache\local-packages\Python312\site-packages\requests\adapters.py", line 667, in send
    resp = conn.urlopen(
           ^^^^^^^^^^^^^
  File "C:\Users\awast\AppData\Local\Packages\PythonSoftwareFoundation.Python.3.12_qbz5n2kfra8p0\LocalCache\local-packages\Python312\site-packages\urllib3\connectionpool.py", line 843, in urlopen
    retries = retries.increment(
              ^^^^^^^^^^^^^^^^^^
  File "C:\Users\awast\AppData\Local\Packages\PythonSoftwareFoundation.Python.3.12_qbz5n2kfra8p0\LocalCache\local-packages\Python312\site-packages\urllib3\util\retry.py", line 519, in increment
    raise MaxRetryError(_pool, url, reason) from reason  # type: ignore[arg-type]
    ^^^^^^^^^^^^^^^^^^^^^^^^^^^^^^^^^^^^^^^^^^^^^^^^^^^
urllib3.exceptions.MaxRetryError: HTTPSConnectionPool(host='www.google.com', port=443): Max retries exceeded with url: /search?q=DFS%20geekforgeeks (Caused by ProxyError('Unable to connect to proxy', ConnectTimeoutError(<urllib3.connection.HTTPSConnection object at 0x000001FDB9347F50>, 'Connection to 103.37.201.178 timed out. (connect timeout=None)')))

During handling of the above exception, another exception occurred:

Traceback (most recent call last):
  File "c:\Users\awast\OneDrive\Desktop\vscode\mdg\b27_project_again\web_scraping\main.py", line 86, in search
    google_search = requests.get(
                    ^^^^^^^^^^^^^
  File "C:\Users\awast\AppData\Local\Packages\PythonSoftwareFoundation.Python.3.12_qbz5n2kfra8p0\LocalCache\local-packages\Python312\site-packages\requests\api.py", line 73, in get
    return request("get", url, params=params, **kwargs)
           ^^^^^^^^^^^^^^^^^^^^^^^^^^^^^^^^^^^^^^^^^^^^
  File "C:\Users\awast\AppData\Local\Packages\PythonSoftwareFoundation.Python.3.12_qbz5n2kfra8p0\LocalCache\local-packages\Python312\site-packages\requests\api.py", line 59, in request
    return session.request(method=method, url=url, **kwargs)
           ^^^^^^^^^^^^^^^^^^^^^^^^^^^^^^^^^^^^^^^^^^^^^^^^^
  File "C:\Users\awast\AppData\Local\Packages\PythonSoftwareFoundation.Python.3.12_qbz5n2kfra8p0\LocalCache\local-packages\Python312\site-packages\requests\sessions.py", line 589, in request
    resp = self.send(prep, **send_kwargs)
           ^^^^^^^^^^^^^^^^^^^^^^^^^^^^^^
  File "C:\Users\awast\AppData\Local\Packages\PythonSoftwareFoundation.Python.3.12_qbz5n2kfra8p0\LocalCache\local-packages\Python312\site-packages\requests\sessions.py", line 703, in send
    r = adapter.send(request, **kwargs)
        ^^^^^^^^^^^^^^^^^^^^^^^^^^^^^^^
  File "C:\Users\awast\AppData\Local\Packages\PythonSoftwareFoundation.Python.3.12_qbz5n2kfra8p0\LocalCache\local-packages\Python312\site-packages\requests\adapters.py", line 694, in send
    raise ProxyError(e, request=request)
requests.exceptions.ProxyError: HTTPSConnectionPool(host='www.google.com', port=443): Max retries exceeded with url: /search?q=DFS%20geekforgeeks (Caused by ProxyError('Unable to connect to proxy', ConnectTimeoutError(<urllib3.connection.HTTPSConnection object at 0x000001FDB9347F50>, 'Connection to 103.37.201.178 timed out. (connect timeout=None)')))

